Workbook

Sheet READ ME
A1: Sheet: System-Level Evaluation Data (Duolingo, Duolingo ABC, Khan academy….) | K1: Sheet: Results by Recommendation Category | U1: Sheet: Results
A2: This sheet presents detailed evaluation data for each analysed gamified system. Each system is represented in a separate tab and contains structured tables used to assess the implementation of usability recommendations. | K2: This sheet presents aggregated results for each analysed gamified system. Each column represents a system. Each row represents evaluation results for a specific recommendation category. | U2: This sheet presents the aggregated results of all analysed gamified systems. Each row represents a single gamified system. Each column represents a specific evaluation metric.
K4: The following categories are evaluated: | U4: System Information
K5: • | L5: General Usability Recommendations (GUR) | U5: • | V5: Age group – target user groups of the system (e.g., children, teenagers, adults, elderly)
A6: 1. Evaluation of Recommended Gamification Elements (URSIGE) | K6: • | L6: Implemented Gamification Elements (IGE) | U6: • | V6: Application domain – domain(s) in which the system is used (e.g., education, health, productivity)
A7: The first table presents the evaluation of usability recommendations for recommended gamification elements (URSIGE) | K7: • | L7: Usability Recommendations for Recommended Gamification Elements (URSIGE) | U7: Popularity Metrics
K8: • | L8: Usability Recommendations for Not Recommended Gamification Elements (URUIGE) | U8: • | V8: User rating – average user rating of the system (from Google Play store)
A9: Three types of usability recommendation sources are included: | K9: General Usability Recommendations (GUR) | U9: • | V9: Rate number – total number of user ratings (from Google Play store)
A10: • | B10: Recommendations by age group and application domain | K10: This section shows how each system satisfies general usability recommendations. | U10: • | V10: Downloads – total number of downloads
A11: • | B11: ISO 9241 recommendations | K11: The following values are provided: | U11: • | V11: Popular rate (DoS) – Degree of Satisfaction metric calculated based on rating distribution; reflects overall user satisfaction and mitigates bias caused by rating volume
A12: • | B12: WCAG 2.2 recommendations | K12: • | L12: Total number of recommendations
A13: For each gamification element (e.g., Quests, Points, Levels), the following implementation levels are recorded: | K13: • | L13: Fulfilled | U13: Usability and Gamification Metrics
A14: • | B14: Fulfilled – the recommendation is fully implemented | K14: • | L14: Partially fulfilled | U14: • | V14: General Usability Recommendations (GUR) – percentage of general usability recommendations fulfilled in the system
A15: • | B15: Partially fulfilled – the recommendation is partially implemented | K15: • | L15: Not fulfilled
A16: • | B16: Not fulfilled – the recommendation is not implemented | K16: • | L16: Total fulfilled (Fulfilled + 0.5 × Partially fulfilled) | U16: • | V16: Implemented Gamification Elements (IGE) – percentage of recommended gamification elements that are implemented in the system
A17: • | B17: Total – total number of applicable recommendations (Fulfilled + 0.5 × Partially fulfilled) | K17: • | L17: Percentage fulfilled
A18: The values in the table indicate the number of recommendations in each category. | K18: Implemented Gamification Elements (IGE) | U18: • | V18: Usability Recommendations for Recommended Gamification Elements (URSIGE) – percentage of usability recommendations fulfilled for recommended gamification elements
A19: A summary table on the right aggregates these values and provides: | K19: This section evaluates how many recommended gamification elements are implemented.
A20: • | B20: Total number of recommendations | K20: The following values are provided: | U20: • | V20: Usability Recommendations for NOT Recommended Gamification Elements (URUIGE) – percentage of usability recommendations fulfilled for gamification elements that were not recommended but are implemented
A21: • | B21: Number of fulfilled recommendations | K21: • | L21: Total number of recommended gamification elements
A22: • | B22: Number of partially fulfilled recommendations | K22: • | L22: Number of elements implemented in the system
A23: • | B23: Number of not fulfilled recommendations | K23: • | L23: Percentage of recommended elements implemented | U23: • | V23: Overall – combined adherence metric calculated from GUR, URSIGE, and URUIGE
A24: • | B24: Overall fulfilment percentage | K24: Usability Recommendations for Recommended Elements (URSIGE) | U24: • | V24: Elements recommendations (URGE) – overall adherence to usability recommendations for gamification elements
A25: 2. Evaluation of Not Recommended Gamification Elements (URUIGE) | K25: This section presents aggregated results of usability recommendation implementation for recommended gamification elements. The values are derived from the system-level evaluation sheets, where each system was analysed individually.
A26: The second table follows the same structure but evaluates usability recommendations for gamification elements that were not recommended by the tool but were still implemented in the system (URUIGE).
A28: The same three recommendation sources are used: | K28: Usability Recommendations for Not Recommended Elements (URUIGE)
A29: • | B29: Recommendations by age group and application domain | K29: This section presents aggregated results of usability recommendation implementation for gamification elements that were not recommended but are implemented in the system. The values are derived from the system-level evaluation sheets.
A30: • | B30: ISO 9241 recommendations
A31: • | B31: WCAG 2.2 recommendations
A32: The evaluation logic is identical to the recommended elements:
A33: • | B33: Fulfilled / Partially fulfilled / Not fulfilled counts are recorded
A34: • | B34: Totals and aggregated results are calculated
A35: A summary table provides overall metrics for non-recommended elements, including:
A36: • | B36: Total number of recommendations
A37: • | B37: Number of fulfilled recommendations
A38: • | B38: Number of partially fulfilled recommendations
A39: • | B39: Number of not fulfilled recommendations
A40: • | B40: Overall fulfilment percentage
A41: 3. Degree of Satisfaction (DoS) Calculation
A42: At the bottom of the sheet, the Degree of Satisfaction (DoS) is calculated for the evaluated application.
...

Sheet Results
A1: Nr | B1: System | C1: Age group | D1: Application domain | E1: User rating | F1: Rate number | G1: Downloads | H1: Popular rate (DoS) | I1: General Usability Recommendations (GUR) | J1: Implemented Gamification Elements (IGE) | K1: Usability Recommendations for Recommended Gamification Elements (URSIGE) | L1: Usability Recommendations for NOT Recommended Gamification Elements (URUIGE) | M1: Overall | N1: Elements recommendations (URGE)
A2: 1 | B2: Duolingo | C2: teenagers, adults, elderly | D2: education | E2: 4.7 | F2: =Duolingo!E36 -> 37473804 | G2: 500000000 | H2: =Duolingo!E40 -> 25.215963 | I2: ='Results by recommendation categ'!C7 -> 0.71052632 | J2: ='Results by recommendation categ'!C10 -> 0.82352941 | K2: ='Results by recommendation categ'!C16 -> 0.71061644 | L2: ='Results by recommendation categ'!C22 -> 0.77894737 | M2: =AVERAGE(Table1[[#This Row],[General Usability Recommendations (GUR)]:[Usability Recommendations for NOT Recommended Gamification Elements (URUIGE)]]) -> 0.75590488 | N2: =AVERAGE(Table1[[#This Row],[Usability Recommendations for Recommended Gamification Elements (URSIGE)]:[Usability Recommendations for NOT Recommended Gamification Elements (URUIGE)]]) -> 0.7447819
A3: 2 | B3: Duolingo ABC | C3: children | D3: education | E3: 4.1 | F3: ='Duolingo ABC'!E29 -> 17919 | G3: 10000000 | H3: ='Duolingo ABC'!E33 -> 13.655184 | I3: ='Results by recommendation categ'!D7 -> 0.73529412 | J3: ='Results by recommendation categ'!D10 -> 0.61538462 | K3: ='Results by recommendation categ'!D16 -> 0.64044944 | L3: ='Results by recommendation categ'!C22 -> 0.77894737 | M3: =AVERAGE(Table1[[#This Row],[General Usability Recommendations (GUR)]:[Usability Recommendations for NOT Recommended Gamification Elements (URUIGE)]]) -> 0.69251888 | N3: =AVERAGE(Table1[[#This Row],[Usability Recommendations for Recommended Gamification Elements (URSIGE)]:[Usability Recommendations for NOT Recommended Gamification Elements (URUIGE)]]) -> 0.7096984
A4: 3 | B4: Khan academy | C4: teenagers, adults, children | D4: education | E4: 4.3 | F4: ='Khan academy'!D37 -> 169688 | G4: 10000000 | H4: ='Khan academy'!D41 -> 16.938119 | I4: ='Results by recommendation categ'!F7 -> 0.66428571 | J4: ='Results by recommendation categ'!F10 -> 0.72727273 | K4: ='Results by recommendation categ'!F16 -> 0.76363636 | L4: ='Results by recommendation categ'!F22 -> 0.77894737 | M4: =AVERAGE(Table1[[#This Row],[General Usability Recommendations (GUR)]:[Usability Recommendations for NOT Recommended Gamification Elements (URUIGE)]]) -> 0.73353554 | N4: =AVERAGE(Table1[[#This Row],[Usability Recommendations for Recommended Gamification Elements (URSIGE)]:[Usability Recommendations for NOT Recommended Gamification Elements (URUIGE)]]) -> 0.77129187
A5: 4 | B5: Khan Academy Kids | C5: children | D5: education | E5: 4.6 | F5: ='Khan academy kids'!D37 -> 52204 | G5: 5000000 | H5: ='Khan academy kids'!D41 -> 15.64274 | I5: ='Results by recommendation categ'!G7 -> 0.69230769 | J5: ='Results by recommendation categ'!G10 -> 0.38461538 | K5: ='Results by recommendation categ'!G16 -> 0.59920635 | L5: ='Results by recommendation categ'!G22 -> 0.71428571 | M5: =AVERAGE(Table1[[#This Row],[General Usability Recommendations (GUR)]:[Usability Recommendations for NOT Recommended Gamification Elements (URUIGE)]]) -> 0.59760379 | N5: =AVERAGE(Table1[[#This Row],[Usability Recommendations for Recommended Gamification Elements (URSIGE)]:[Usability Recommendations for NOT Recommended Gamification Elements (URUIGE)]]) -> 0.65674603
A6: 5 | B6: Headspace | C6: teenagers, adults, elderly | D6: mental health | E6: 4.4 | F6: =Headspace!D37 -> 336619 | G6: 10000000 | H6: =Headspace!D41 -> 18.176333 | I6: ='Results by recommendation categ'!H7 -> 0.63888889 | J6: ='Results by recommendation categ'!H10 -> 0.375 | K6: ='Results by recommendation categ'!H16 -> 0.7 | L6: ='Results by recommendation categ'!H22 -> 0.90909091 | M6: =AVERAGE(Table1[[#This Row],[General Usability Recommendations (GUR)]:[Usability Recommendations for NOT Recommended Gamification Elements (URUIGE)]]) -> 0.65574495 | N6: =AVERAGE(Table1[[#This Row],[Usability Recommendations for Recommended Gamification Elements (URSIGE)]:[Usability Recommendations for NOT Recommended Gamification Elements (URUIGE)]]) -> 0.80454545
A7: 6 | B7: Fitbit | C7: teenagers, adults, elderly | D7: sport fitness | E7: 4 | F7: =FITBIT!E27 -> 1209912 | G7: 100000000 | H7: =FITBIT!E31 -> 19.772068 | I7: ='Results by recommendation categ'!E7 -> 0.90909091 | J7: ='Results by recommendation categ'!E10 -> 0.58333333 | K7: ='Results by recommendation categ'!E16 -> 0.70247934 | L7: ='Results by recommendation categ'!E22 -> 0.609375 | M7: =AVERAGE(Table1[[#This Row],[General Usability Recommendations (GUR)]:[Usability Recommendations for NOT Recommended Gamification Elements (URUIGE)]]) -> 0.70106965 | N7: =AVERAGE(Table1[[#This Row],[Usability Recommendations for Recommended Gamification Elements (URSIGE)]:[Usability Recommendations for NOT Recommended Gamification Elements (URUIGE)]]) -> 0.65592717
A8: 7 | B8: CodeAcademy Go | C8: teenagers, adults | D8: education | E8: 4.7 | F8: =CodeAcademyGo!D37 -> 38861 | G8: 1000000 | H8: =CodeAcademyGo!D41 -> 15.302607 | I8: ='Results by recommendation categ'!AF7 -> 0.75 | J8: ='Results by recommendation categ'!AF10 -> 0.52941176 | K8: ='Results by recommendation categ'!AF16 -> 0.79920213 | L8: ='Results by recommendation categ'!AF22 -> 0.89583333 | M8: =AVERAGE(Table1[[#This Row],[General Usability Recommendations (GUR)]:[Usability Recommendations for NOT Recommended Gamification Elements (URUIGE)]]) -> 0.74361181 | N8: =AVERAGE(Table1[[#This Row],[Usability Recommendations for Recommended Gamification Elements (URSIGE)]:[Usability Recommendations for NOT Recommended Gamification Elements (URUIGE)]]) -> 0.84751773
A9: 8 | B9: Fortune city | C9: teenagers, adults | D9: finance | E9: 4.5 | F9: ='Fortune city'!D37 -> 116667 | G9: 1000000 | H9: ='Fortune city'!D41 -> 16.832046 | I9: ='Results by recommendation categ'!I7 -> 0.7734375 | J9: ='Results by recommendation categ'!I10 -> 0.52631579 | K9: ='Results by recommendation categ'!I16 -> 0.7943662 | L9: ='Results by recommendation categ'!I22 -> 0.75 | M9: =AVERAGE(Table1[[#This Row],[General Usability Recommendations (GUR)]:[Usability Recommendations for NOT Recommended Gamification Elements (URUIGE)]]) -> 0.71102987 | N9: =AVERAGE(Table1[[#This Row],[Usability Recommendations for Recommended Gamification Elements (URSIGE)]:[Usability Recommendations for NOT Recommended Gamification Elements (URUIGE)]]) -> 0.7721831
A10: 9 | B10: Habitica | C10: teenagers, adults | D10: habits formation and productivity | E10: 4.7 | F10: =Habitica!D37 -> 68118 | G10: 5000000 | H10: =Habitica!D41 -> 16.112313 | I10: ='Results by recommendation categ'!J7 -> 0.88095238 | J10: ='Results by recommendation categ'!J10 -> 0.73333333 | K10: ='Results by recommendation categ'!J16 -> 0.65206186 | L10: ='Results by recommendation categ'!J22 -> 0.80487805 | M10: =AVERAGE(Table1[[#This Row],[General Usability Recommendations (GUR)]:[Usability Recommendations for NOT Recommended Gamification Elements (URUIGE)]]) -> 0.7678064 | N10: =AVERAGE(Table1[[#This Row],[Usability Recommendations for Recommended Gamification Elements (URSIGE)]:[Usability Recommendations for NOT Recommended Gamification Elements (URUIGE)]]) -> 0.72846995
A11: 10 | B11: Memrise | C11: teenagers, adults | D11: education | E11: 4.6 | F11: =Memrise!D37 -> 1570598 | G11: 10000000 | H11: =Memrise!D41 -> 20.553736 | I11: ='Results by recommendation categ'!K7 -> 0.71052632 | J11: ='Results by recommendation categ'!K10 -> 0.52941176 | K11: ='Results by recommendation categ'!K16 -> 0.68274854 | M11: =AVERAGE(Table1[[#This Row],[General Usability Recommendations (GUR)]:[Usability Recommendations for NOT Recommended Gamification Elements (URUIGE)]]) -> 0.64089554 | N11: =AVERAGE(Table1[[#This Row],[Usability Recommendations for Recommended Gamification Elements (URSIGE)]:[Usability Recommendations for NOT Recommended Gamification Elements (URUIGE)]]) -> 0.68274854
A12: 11 | B12: Brilliant | C12: teenagers, adults, elderly | D12: education | E12: 4.6 | F12: =Brilliant!D37 -> 98290 | G12: 5000000 | H12: =Brilliant!D41 -> 16.555623 | I12: ='Results by recommendation categ'!L7 -> 0.81081081 | J12: ='Results by recommendation categ'!L10 -> 0.70588235 | K12: ='Results by recommendation categ'!L16 -> 0.79761905 | M12: =AVERAGE(Table1[[#This Row],[General Usability Recommendations (GUR)]:[Usability Recommendations for NOT Recommended Gamification Elements (URUIGE)]]) -> 0.7714374 | N12: =AVERAGE(Table1[[#This Row],[Usability Recommendations for Recommended Gamification Elements (URSIGE)]:[Usability Recommendations for NOT Recommended Gamification Elements (URUIGE)]]) -> 0.79761905
A13: 12 | B13: Fabulous | C13: teenagers, adults, elderly | D13: mental health, habits formation and productivity | E13: 4.4 | F13: =Fabulous!D38 -> 580767 | G13: 10000000 | H13: =Fabulous!D42 -> 18.995595 | I13: ='Results by recommendation categ'!P7 -> 0.73809524 | J13: ='Results by recommendation categ'!P10 -> 0.52631579 | K13: ='Results by recommendation categ'!P16 -> 0.80952381 | L13: ='Results by recommendation categ'!P22 -> 0.73333333 | M13: =AVERAGE(Table1[[#This Row],[General Usability Recommendations (GUR)]:[Usability Recommendations for NOT Recommended Gamification Elements (URUIGE)]]) -> 0.70181704 | N13: =AVERAGE(Table1[[#This Row],[Usability Recommendations for Recommended Gamification Elements (URSIGE)]:[Usability Recommendations for NOT Recommended Gamification Elements (URUIGE)]]) -> 0.77142857
A14: 13 | B14: Clarify | C14: teenagers, adults | D14: mental health | E14: 4.2 | F14: ='Clarify by fabulous'!D38 -> 7378 | G14: 500000 | H14: ='Clarify by fabulous'!D42 -> 12.526939 | I14: ='Results by recommendation categ'!Q7 -> 0.7 | J14: ='Results by recommendation categ'!Q10 -> 0.625 | K14: ='Results by recommendation categ'!Q16 -> 0.75409836 | L14: ='Results by recommendation categ'!Q22 -> 0.7027027 | M14: =AVERAGE(Table1[[#This Row],[General Usability Recommendations (GUR)]:[Usability Recommendations for NOT Recommended Gamification Elements (URUIGE)]]) -> 0.69545027 | N14: =AVERAGE(Table1[[#This Row],[Usability Recommendations for Recommended Gamification Elements (URSIGE)]:[Usability Recommendations for NOT Recommended Gamification Elements (URUIGE)]]) -> 0.72840053
A15: 14 | B15: Strava | C15: teenagers, adults, elderly | D15: sport fitness | E15: 4.5 | F15: =Strava!D38 -> 974938 | G15: 50000000 | H15: =Strava!D42 -> 19.774658 | I15: ='Results by recommendation categ'!M7 -> 0.86363636 | J15: ='Results by recommendation categ'!M10 -> 0.83333333 | K15: ='Results by recommendation categ'!M16 -> 0.77232143 | L15: ='Results by recommendation categ'!M22 -> 0.82 | M15: =AVERAGE(Table1[[#This Row],[General Usability Recommendations (GUR)]:[Usability Recommendations for NOT Recommended Gamification Elements (URUIGE)]]) -> 0.82232278 | N15: =AVERAGE(Table1[[#This Row],[Usability Recommendations for Recommended Gamification Elements (URSIGE)]:[Usability Recommendations for NOT Recommended Gamification Elements (URUIGE)]]) -> 0.79616071
A16: 15 | B16: SuperBetter | C16: teenagers, adults, elderly | D16: mental health | E16: 4.2 | F16: =SuperBetter!D38 -> 6542 | G16: 100000 | H16: =SuperBetter!D42 -> 12.424219 | I16: ='Results by recommendation categ'!S7 -> 0.66666667 | J16: ='Results by recommendation categ'!S10 -> 0.625 | K16: ='Results by recommendation categ'!S16 -> 0.72635135 | L16: ='Results by recommendation categ'!S22 -> 0.73504274 | M16: =AVERAGE(Table1[[#This Row],[General Usability Recommendations (GUR)]:[Usability Recommendations for NOT Recommended Gamification Elements (URUIGE)]]) -> 0.68826519 | N16: =AVERAGE(Table1[[#This Row],[Usability Recommendations for Recommended Gamification Elements (URSIGE)]:[Usability Recommendations for NOT Recommended Gamification Elements (URUIGE)]]) -> 0.73069704
A17: 16 | B17: Lumosity | C17: teenagers, adults, elderly | D17: mental health, healthcare | E17: 4.5 | F17: =Lumosity!D38 -> 288463 | G17: 10000000 | H17: =Lumosity!D42 -> 18.079137 | I17: ='Results by recommendation categ'!N7 -> 0.75609756 | J17: ='Results by recommendation categ'!N10 -> 0.73333333 | K17: ='Results by recommendation categ'!N16 -> 0.80229226 | L17: ='Results by recommendation categ'!N22 -> 0.83064516 | M17: =AVERAGE(Table1[[#This Row],[General Usability Recommendations (GUR)]:[Usability Recommendations for NOT Recommended Gamification Elements (URUIGE)]]) -> 0.78059208 | N17: =AVERAGE(Table1[[#This Row],[Usability Recommendations for Recommended Gamification Elements (URSIGE)]:[Usability Recommendations for NOT Recommended Gamification Elements (URUIGE)]]) -> 0.81646871
A18: 17 | B18: Sidekick Health | C18: adults, elderly | D18: healthy eating, healthy living | E18: 3.7 | F18: ='Sidekick Health'!D37 -> 148 | G18: 10000 | H18: ='Sidekick Health'!D41 -> 6.3715589 | I18: ='Results by recommendation categ'!V7 -> 0.58333333 | J18: ='Results by recommendation categ'!V10 -> 0.35294118 | K18: ='Results by recommendation categ'!V16 -> 0.63571429 | L18: ='Results by recommendation categ'!V22 -> 0.59821429 | M18: =AVERAGE(Table1[[#This Row],[General Usability Recommendations (GUR)]:[Usability Recommendations for NOT Recommended Gamification Elements (URUIGE)]]) -> 0.54255077 | N18: =AVERAGE(Table1[[#This Row],[Usability Recommendations for Recommended Gamification Elements (URSIGE)]:[Usability Recommendations for NOT Recommended Gamification Elements (URUIGE)]]) -> 0.61696429
A19: 18 | B19: ABCmouse | C19: children | D19: education | E19: 3.7 | F19: =ABCmouse!D38 -> 94281 | G19: 10000000 | H19: =ABCmouse!D42 -> 15.524698 | I19: ='Results by recommendation categ'!O7 -> 0.73584906 | J19: ='Results by recommendation categ'!O10 -> 0.76923077 | K19: ='Results by recommendation categ'!O16 -> 0.75703325 | L19: ='Results by recommendation categ'!O22 -> 0.76209677 | M19: =AVERAGE(Table1[[#This Row],[General Usability Recommendations (GUR)]:[Usability Recommendations for NOT Recommended Gamification Elements (URUIGE)]]) -> 0.75605246 | N19: =AVERAGE(Table1[[#This Row],[Usability Recommendations for Recommended Gamification Elements (URSIGE)]:[Usability Recommendations for NOT Recommended Gamification Elements (URUIGE)]]) -> 0.75956501
A20: 19 | B20: CogniFit | C20: teenagers, adults, elderly | D20: mental health, healthcare | E20: 3.9 | F20: =CogniFit!D40 -> 9749 | G20: 1000000 | H20: =CogniFit!D44 -> 12.607307 | I20: ='Results by recommendation categ'!T7 -> 0.78571429 | J20: ='Results by recommendation categ'!T10 -> 0.625 | K20: ='Results by recommendation categ'!T16 -> 0.76969697 | L20: ='Results by recommendation categ'!T22 -> 0.96296296 | M20: =AVERAGE(Table1[[#This Row],[General Usability Recommendations (GUR)]:[Usability Recommendations for NOT Recommended Gamification Elements (URUIGE)]]) -> 0.78584355 | N20: =AVERAGE(Table1[[#This Row],[Usability Recommendations for Recommended Gamification Elements (URSIGE)]:[Usability Recommendations for NOT Recommended Gamification Elements (URUIGE)]]) -> 0.86632997
A21: 20 | B21: Shape by fabulous | C21: teenagers, adults | D21: healthy eating, healthy living | E21: 4 | F21: ='Shape by fabulous'!D38 -> 1197 | G21: 50000 | H21: ='Shape by fabulous'!D42 -> 9.712011 | I21: ='Results by recommendation categ'!R7 -> 0.5 | J21: ='Results by recommendation categ'!R10 -> 0.54545455 | K21: ='Results by recommendation categ'!R16 -> 0.69666667 | L21: ='Results by recommendation categ'!R22 -> 0.640625 | M21: =AVERAGE(Table1[[#This Row],[General Usability Recommendations (GUR)]:[Usability Recommendations for NOT Recommended Gamification Elements (URUIGE)]]) -> 0.59568655 | N21: =AVERAGE(Table1[[#This Row],[Usability Recommendations for Recommended Gamification Elements (URSIGE)]:[Usability Recommendations for NOT Recommended Gamification Elements (URUIGE)]]) -> 0.66864583
A22: 21 | B22: Habit Tracker - Habit Mate | C22: teenagers, adults, elderly | D22: habits formation and productivity | E22: 3.7 | F22: ='Habit Tracker - Habit Mate'!D38 -> 55 | G22: 10000 | H22: ='Habit Tracker - Habit Mate'!D42 -> 5.0223678 | I22: ='Results by recommendation categ'!Y7 -> 0.7 | J22: ='Results by recommendation categ'!Y10 -> 0.13333333 | K22: ='Results by recommendation categ'!Y16 -> 0.56164384 | L22: ='Results by recommendation categ'!Y22 -> 0.68181818 | M22: =AVERAGE(Table1[[#This Row],[General Usability Recommendations (GUR)]:[Usability Recommendations for NOT Recommended Gamification Elements (URUIGE)]]) -> 0.51919884 | N22: =AVERAGE(Table1[[#This Row],[Usability Recommendations for Recommended Gamification Elements (URSIGE)]:[Usability Recommendations for NOT Recommended Gamification Elements (URUIGE)]]) -> 0.62173101
A23: 22 | B23: TaskGame - Gamify your life | C23: teenagers, adults, elderly | D23: habits formation and productivity | E23: 3.8 | F23: ='TaskGame - Gamify your life'!D37 -> 63 | G23: 1000 | H23: ='TaskGame - Gamify your life'!D41 -> 5.5014391 | I23: ='Results by recommendation categ'!X7 -> 0.69047619 | J23: ='Results by recommendation categ'!X10 -> 0.33333333 | K23: ='Results by recommendation categ'!X16 -> 0.61340206 | L23: ='Results by recommendation categ'!X22 -> 0.66666667 | M23: =AVERAGE(Table1[[#This Row],[General Usability Recommendations (GUR)]:[Usability Recommendations for NOT Recommended Gamification Elements (URUIGE)]]) -> 0.57596956 | N23: =AVERAGE(Table1[[#This Row],[Usability Recommendations for Recommended Gamification Elements (URSIGE)]:[Usability Recommendations for NOT Recommended Gamification Elements (URUIGE)]]) -> 0.64003436
A24: 23 | B24: Habio - Simple Habit Tracker | C24: teenagers, adults | D24: habits formation and productivity | E24: 2.9 | F24: ='Habio - Simple Habit Tracker'!D37 -> 33 | G24: 1000 | H24: ='Habio - Simple Habit Tracker'!D41 -> -3.0531113 | I24: ='Results by recommendation categ'!U7 -> 0.6 | J24: ='Results by recommendation categ'!U10 -> 0.4 | K24: ='Results by recommendation categ'!U16 -> 0.65898618 | L24: ='Results by recommendation categ'!U22 -> 0.73026316 | M24: =AVERAGE(Table1[[#This Row],[General Usability Recommendations (GUR)]:[Usability Recommendations for NOT Recommended Gamification Elements (URUIGE)]]) -> 0.59731233 | N24: =AVERAGE(Table1[[#This Row],[Usability Recommendations for Recommended Gamification Elements (URSIGE)]:[Usability Recommendations for NOT Recommended Gamification Elements (URUIGE)]]) -> 0.69462467
A25: 24 | B25: Walken | C25: teenagers, adults | D25: sport fitness | E25: 2.3 | F25: =Walken!D38 -> 28745 | G25: 1000000 | H25: =Walken!D42 -> -13.810923 | I25: ='Results by recommendation categ'!AG7 -> 0.5 | J25: ='Results by recommendation categ'!AG10 -> 0.33333333 | K25: ='Results by recommendation categ'!AG16 -> 0.47887324 | L25: ='Results by recommendation categ'!AG22 -> 0.55555556 | M25: =AVERAGE(Table1[[#This Row],[General Usability Recommendations (GUR)]:[Usability Recommendations for NOT Recommended Gamification Elements (URUIGE)]]) -> 0.46694053 | N25: =AVERAGE(Table1[[#This Row],[Usability Recommendations for Recommended Gamification Elements (URSIGE)]:[Usability Recommendations for NOT Recommended Gamification Elements (URUIGE)]]) -> 0.5172144
A26: 25 | B26: Narn: Habit Tracker & Goals | C26: teenagers, adults | D26: habits formation and productivity | E26: 2.9 | F26: ='Narn Habit Tracker & Goals'!D37 -> 75 | G26: 1000 | H26: ='Narn Habit Tracker & Goals'!D41 -> -4.0443941 | I26: ='Results by recommendation categ'!AH7 -> 0.64285714 | J26: ='Results by recommendation categ'!AH10 -> 0.46666667 | K26: ='Results by recommendation categ'!AH16 -> 0.44318182 | L26: ='Results by recommendation categ'!AH22 -> 0.25 | M26: =AVERAGE(Table1[[#This Row],[General Usability Recommendations (GUR)]:[Usability Recommendations for NOT Recommended Gamification Elements (URUIGE)]]) -> 0.45067641 | N26: =AVERAGE(Table1[[#This Row],[Usability Recommendations for Recommended Gamification Elements (URSIGE)]:[Usability Recommendations for NOT Recommended Gamification Elements (URUIGE)]]) -> 0.34659091
A27: 26 | B27: Aula Lengua | C27: children | D27: education | E27: 2.7 | F27: ='Aula Lengua'!D36 -> 43 | G27: 10000 | H27: ='Aula Lengua'!D40 -> -4.1127001 | I27: ='Results by recommendation categ'!AD7 -> 0.55 | J27: ='Results by recommendation categ'!AD10 -> 0.30769231 | K27: ='Results by recommendation categ'!AD16 -> 0.48351648 | L27: ='Results by recommendation categ'!AD22 -> 0.54166667 | M27: =AVERAGE(Table1[[#This Row],[General Usability Recommendations (GUR)]:[Usability Recommendations for NOT Recommended Gamification Elements (URUIGE)]]) -> 0.47071886 | N27: =AVERAGE(Table1[[#This Row],[Usability Recommendations for Recommended Gamification Elements (URSIGE)]:[Usability Recommendations for NOT Recommended Gamification Elements (URUIGE)]]) -> 0.51259158
A28: 27 | B28: Foursquare Swarm: Check In | C28: teenagers, adults | D28: entertainment/social media | E28: 2.9 | F28: ='Foursquare Swarm - Check In'!D37 -> 429150 | G28: 10000000 | H28: ='Foursquare Swarm - Check In'!D41 -> -15.652201 | I28: ='Results by recommendation categ'!Z7 -> 0.57258065 | J28: ='Results by recommendation categ'!Z10 -> 0.13157895 | K28: ='Results by recommendation categ'!Z16 -> 0.63333333 | M28: =AVERAGE(Table1[[#This Row],[General Usability Recommendations (GUR)]:[Usability Recommendations for NOT Recommended Gamification Elements (URUIGE)]]) -> 0.44583098 | N28: =AVERAGE(Table1[[#This Row],[Usability Recommendations for Recommended Gamification Elements (URSIGE)]:[Usability Recommendations for NOT Recommended Gamification Elements (URUIGE)]]) -> 0.63333333
A29: 28 | B29: Roomsy: Chores Tracker & Chart | C29: teenagers, adults, elderly | D29: habits formation and productivity | E29: 2.6 | F29: ='Roomsy Chores Tracker & Chart'!D38 -> 10 | G29: 1000 | H29: ='Roomsy Chores Tracker & Chart'!D42 -> -2.3219281 | I29: ='Results by recommendation categ'!AC7 -> 0.675 | J29: ='Results by recommendation categ'!AC10 -> 0.26666667 | K29: ='Results by recommendation categ'!AC16 -> 0.69078947 | L29: ='Results by recommendation categ'!AC22 -> 0.671875 | M29: =AVERAGE(Table1[[#This Row],[General Usability Recommendations (GUR)]:[Usability Recommendations for NOT Recommended Gamification Elements (URUIGE)]]) -> 0.57608279 | N29: =AVERAGE(Table1[[#This Row],[Usability Recommendations for Recommended Gamification Elements (URSIGE)]:[Usability Recommendations for NOT Recommended Gamification Elements (URUIGE)]]) -> 0.68133224
A30: 29 | B30: Fitmint: Walk & Steps Tracker | C30: teenagers, adults, elderly | D30: sport fitness | E30: 2.8 | F30: ='Fitmint - Walk & Steps Tracker'!D38 -> 1253 | G30: 100000 | H30: ='Fitmint - Walk & Steps Tracker'!D42 -> 7.2317012 | I30: ='Results by recommendation categ'!W7 -> 0.68181818 | J30: ='Results by recommendation categ'!W10 -> 0.58333333 | K30: ='Results by recommendation categ'!W16 -> 0.65625 | L30: ='Results by recommendation categ'!X22 -> 0.66666667 | M30: =AVERAGE(Table1[[#This Row],[General Usability Recommendations (GUR)]:[Usability Recommendations for NOT Recommended Gamification Elements (URUIGE)]]) -> 0.64701705 | N30: =AVERAGE(Table1[[#This Row],[Usability Recommendations for Recommended Gamification Elements (URSIGE)]:[Usability Recommendations for NOT Recommended Gamification Elements (URUIGE)]]) -> 0.66145833
A31: 30 | B31: Workout Quest - Gamified Gym | C31: teenagers, adults | D31: sport fitness | E31: 3.7 | F31: ='Workout Quest - Gamified Gym '!D37 -> 154 | G31: 10000 | H31: ='Workout Quest - Gamified Gym '!D41 -> 5.9401668 | I31: ='Results by recommendation categ'!AI7 -> 0.75 | J31: ='Results by recommendation categ'!AI10 -> 0.5 | K31: ='Results by recommendation categ'!AI16 -> 0.61678832 | L31: ='Results by recommendation categ'!AI22 -> 0.60714286 | M31: =AVERAGE(Table1[[#This Row],[General Usability Recommendations (GUR)]:[Usability Recommendations for NOT Recommended Gamification Elements (URUIGE)]]) -> 0.61848279 | N31: =AVERAGE(Table1[[#This Row],[Usability Recommendations for Recommended Gamification Elements (URSIGE)]:[Usability Recommendations for NOT Recommended Gamification Elements (URUIGE)]]) -> 0.61196559
A32: 31 | B32: Death Reminder App | C32: teenagers, adults | D32: mental health | E32: 2.1 | F32: ='Death Reminder App'!D37 -> 154 | G32: 1000 | H32: ='Death Reminder App'!D41 -> 5.9401668 | I32: ='Results by recommendation categ'!AA7 -> 0.47368421 | J32: ='Results by recommendation categ'!AA10 -> 0.375 | K32: ='Results by recommendation categ'!AA16 -> 0.58080808 | L32: ='Results by recommendation categ'!AA22 -> 0.48275862 | M32: =AVERAGE(Table1[[#This Row],[General Usability Recommendations (GUR)]:[Usability Recommendations for NOT Recommended Gamification Elements (URUIGE)]]) -> 0.47806273 | N32: =AVERAGE(Table1[[#This Row],[Usability Recommendations for Recommended Gamification Elements (URSIGE)]:[Usability Recommendations for NOT Recommended Gamification Elements (URUIGE)]]) -> 0.53178335
A33: 32 | B33: Pharmacy Crack: Rx Drug Trivia | C33: teenagers, adults | D33: education, healthcare | E33: 2.2 | F33: ='Pharmacy Crack Rx Drug Trivia'!D36 -> 37 | G33: 10000 | H33: ='Pharmacy Crack Rx Drug Trivia'!D40 -> -4.5046204 | I33: ='Results by recommendation categ'!AE7 -> 0.55128205 | J33: ='Results by recommendation categ'!AE10 -> 0.44444444 | K33: ='Results by recommendation categ'!AE16 -> 0.4845679 | L33: ='Results by recommendation categ'!AE22 -> 0.54255319 | M33: =AVERAGE(Table1[[#This Row],[General Usability Recommendations (GUR)]:[Usability Recommendations for NOT Recommended Gamification Elements (URUIGE)]]) -> 0.5057119 | N33: =AVERAGE(Table1[[#This Row],[Usability Recommendations for Recommended Gamification Elements (URSIGE)]:[Usability Recommendations for NOT Recommended Gamification Elements (URUIGE)]]) -> 0.51356055
A34: 33 | B34: Gametize: Explore Experiences | C34: teenagers, adults | D34: education, habits formation and productivity | E34: 3.2 | F34: ='Gametize Explore Experiences'!D37 -> 131 | G34: 50000 | H34: ='Gametize Explore Experiences'!D41 -> 4.3291236 | I34: ='Results by recommendation categ'!AB7 -> 0.44594595 | J34: ='Results by recommendation categ'!AB10 -> 0.25 | K34: ='Results by recommendation categ'!AB16 -> 0.53626943 | L34: ='Results by recommendation categ'!AB22 -> 0.61111111 | M34: =AVERAGE(Table1[[#This Row],[General Usability Recommendations (GUR)]:[Usability Recommendations for NOT Recommended Gamification Elements (URUIGE)]]) -> 0.46083162 | N34: =AVERAGE(Table1[[#This Row],[Usability Recommendations for Recommended Gamification Elements (URSIGE)]:[Usability Recommendations for NOT Recommended Gamification Elements (URUIGE)]]) -> 0.57369027
I35: =AVERAGE(I2:I34) -> 0.67997447 | J35: =AVERAGE(J2:J34) -> 0.50589339 | K35: =AVERAGE(K2:K34) -> 0.66680286 | L35: =AVERAGE(L2:L34) -> 0.69380019 | M35: =AVERAGE(M2:M34) -> 0.63492654 | N35: =AVERAGE(N2:N34) -> 0.68079092

Sheet Results by recommendation categ
A1: Category | B1: Gamification system | C1: Duolingo | D1: Duolingo ABC | E1: Fitbit | F1: Khan academy | G1: Khan academy kids | H1: Headspace | I1: Fortune city | J1: Habitica | K1: Memrise | L1: Brilliant | M1: Strava | N1: Lumosity | O1: ABC Mouse | P1: Fabulous | Q1: Clarify | R1: Shape | S1: SuperBetter | T1: CogniFit | U1: Habio | V1: Sidekick | W1: Fitmint | X1: TaskGame - Gamify your life | Y1: Habit Tracker - Habit Mate | Z1: Foursquare Swarm: Check In | AA1: Death reminder app | AB1: Gametize: Explore Experiences | AC1: Roomsy: Chores Tracker & Chart | AD1: Aula Lengua | AE1: Pharmacy Crack: Rx Drug Trivia | AF1: CodeAcademy Go | AG1: Walken | AH1: Narn: Habit Tracker & Goals | AI1: Workout Quest - Gamified Gym
A2: General Usability Recommendations (GUR) | B2: Total number of general recommendations provided | C2: 38 | D2: 51 | E2: 11 | F2: =F3+F4+F5 -> 70 | G2: =G3+G4+G5 -> 52 | H2: =SUM(H3:H5) -> 18 | I2: =SUM(I3:I5) -> 64 | J2: =SUM(J3:J5) -> 21 | K2: =SUM(K3:K5) -> 38 | L2: =L3+L4+L5 -> 37 | M2: 11 | N2: =N3+N4+N5 -> 41 | O2: =O5+O4+O3 -> 53 | P2: =P3+P4+P5 -> 21 | Q2: =Q3+Q4+Q5 -> 20 | R2: 3 | S2: =S3+S4+S5 -> 21 | T2: =T3+T4+T5 -> 21 | U2: =U3+U4+U5 -> 20 | V2: =V3+V4+V5 -> 24 | W2: =W3+W4+W5 -> 11 | X2: =X3+X4+X5 -> 21 | Y2: =Y3+Y4+Y5 -> 20 | Z2: =Z3+Z4+Z5 -> 62 | ... AI2: =AI3+AI4+AI5 -> 2
B3: Fulfilled | C3: 24 | D3: 34 | E3: 10 | F3: 39 | G3: 34 | H3: 10 | I3: 45 | J3: 16 | K3: 24 | L3: 27 | M3: 9 | N3: 26 | O3: 36 | P3: 14 | Q3: 12 | R3: 1 | S3: 13 | T3: 15 | U3: 8 | V3: 11 | W3: 6 | X3: 12 | Y3: 12 | Z3: 30 | AA3: 7 | AB3: 12 | AC3: 12 | AD3: 22 | AE3: 16 | AF3: 25 | AG3: 1 | AH3: 10 | AI3: 1
B4: Partially fulfilled | C4: 6 | D4: 7 | E4: 0 | F4: 15 | G4: 4 | H4: 3 | I4: 9 | J4: 5 | K4: 6 | L4: 6 | M4: 1 | N4: 10 | O4: 6 | P4: 3 | Q4: 4 | R4: 1 | S4: 2 | T4: 3 | U4: 8 | V4: 6 | W4: 3 | X4: 5 | Y4: 4 | Z4: 11 | AA4: 4 | AB4: 9 | AC4: 3 | AD4: 11 | AE4: 11 | AF4: 4 | AG4: 0 | AH4: 7 | AI4: 1
B5: Not fulfilled | C5: 8 | D5: 10 | E5: 1 | F5: 16 | G5: 14 | H5: 5 | I5: 10 | J5: 0 | K5: 8 | L5: 4 | M5: 1 | N5: 5 | O5: 11 | P5: 4 | Q5: 4 | R5: 1 | S5: 6 | T5: 3 | U5: 4 | V5: 7 | W5: 2 | X5: 4 | Y5: 4 | Z5: 21 | AA5: 8 | AB5: 16 | AC5: 5 | AD5: 17 | AE5: 12 | AF5: 7 | AG5: 1 | AH5: 4 | AI5: 0
B6: Total fulfilled | C6: =(C3+(C4*0.5)) -> 27 | D6: =(D3+(D4*0.5)) -> 37.5 | E6: =(E3+(E4*0.5)) -> 10 | F6: =(F3+(F4*0.5)) -> 46.5 | G6: =(G3+(G4*0.5)) -> 36 | H6: =(H3+(H4*0.5)) -> 11.5 | I6: =(I3+(I4*0.5)) -> 49.5 | J6: =(J3+(J4*0.5)) -> 18.5 | ... AI6: =(AI3+(AI4*0.5)) -> 1.5
B7: Percentage fulfilled | C7: =C6/C2 -> 0.71052632 | D7: =D6/D2 -> 0.73529412 | E7: =E6/E2 -> 0.90909091 | F7: =F6/F2 -> 0.66428571 | G7: =G6/G2 -> 0.69230769 | H7: =H6/H2 -> 0.63888889 | I7: =I6/I2 -> 0.7734375 | J7: =J6/J2 -> 0.88095238 | ... AI7: =AI6/AI2 -> 0.75
A8: Implemented Gamification Elements (IGE) | B8: Total number of recommended gamification elements | C8: 17 | D8: 13 | E8: 12 | F8: 22 | G8: 13 | H8: 8 | I8: 38 | J8: 15 | K8: 17 | L8: 17 | M8: 12 | N8: 15 | O8: 13 | P8: 19 | Q8: 8 | R8: 11 | S8: 8 | T8: 8 | U8: 15 | V8: 17 | W8: 12 | X8: 15 | Y8: 15 | Z8: 38 | AA8: 8 | AB8: 24 | AC8: 15 | AD8: 13 | AE8: 18 | AF8: 17 | AG8: 12 | AH8: 15 | AI8: 12
B9: Elements present in the system out of recommended elements | C9: 14 | D9: 8 | E9: 7 | F9: 16 | G9: 5 | H9: 3 | I9: 20 | J9: 11 | K9: 9 | L9: 12 | M9: 10 | N9: 11 | O9: 10 | P9: 10 | Q9: 5 | R9: 6 | S9: 5 | T9: 5 | U9: 6 | V9: 6 | W9: 7 | X9: 5 | Y9: 2 | Z9: 5 | AA9: 3 | AB9: 6 | AC9: 4 | AD9: 4 | AE9: 8 | AF9: 9 | AG9: 4 | AH9: 7 | AI9: 6
B10: Percentage met | C10: =C9/C8 -> 0.82352941 | D10: =D9/D8 -> 0.61538462 | E10: =E9/E8 -> 0.58333333 | F10: =F9/F8 -> 0.72727273 | G10: =G9/G8 -> 0.38461538 | H10: =H9/H8 -> 0.375 | I10: =I9/I8 -> 0.52631579 | J10: =J9/J8 -> 0.73333333 | ... AI10: =AI9/AI8 -> 0.5
A11: Usability Recommendations for Recommended Gamification Elements (URSIGE) | B11: Total number of recommendations provided for recommended gamification elements | C11: 584 | D11: 267 | E11: 121 | F11: 550 | G11: 126 | H11: 85 | I11: 355 | J11: 194 | K11: 342 | L11: 294 | M11: 224 | N11: 349 | O11: 391 | P11: 210 | Q11: 122 | R11: 150 | S11: 148 | T11: 165 | U11: 217 | V11: 140 | W11: 128 | X11: 97 | Y11: 73 | Z11: 105 | AA11: 99 | AB11: 193 | AC11: 76 | AD11: 182 | AE11: 324 | AF11: 376 | AG11: 71 | AH11: 132 | AI11: 137
B12: Fulfilled | C12: 354 | D12: 143 | E12: 75 | F12: 377 | G12: 65 | H12: 53 | I12: 256 | J12: 115 | K12: 207 | L12: 213 | M12: 155 | N12: 258 | O12: 257 | P12: 154 | Q12: 80 | R12: 92 | S12: 97 | T12: 113 | U12: 122 | V12: 76 | W12: 73 | X12: 47 | Y12: 31 | Z12: 56 | AA12: 50 | AB12: 84 | AC12: 45 | AD12: 66 | AE12: 131 | AF12: 269 | AG12: 26 | AH12: 46 | AI12: 75
B13: Partially fulfilled | C13: 122 | D13: 56 | E13: 20 | F13: 86 | G13: 21 | H13: 13 | I13: 52 | J13: 23 | K13: 53 | L13: 43 | M13: 36 | N13: 44 | O13: 78 | P13: 32 | Q13: 24 | R13: 25 | S13: 21 | T13: 28 | U13: 42 | V13: 26 | W13: 22 | X13: 25 | Y13: 20 | Z13: 21 | AA13: 15 | AB13: 39 | AC13: 15 | AD13: 44 | AE13: 52 | AF13: 63 | AG13: 16 | AH13: 25 | AI13: 19
B14: Not fulfilled | C14: 108 | D14: 67 | E14: 26 | F14: 87 | G14: 40 | H14: 19 | I14: 51 | J14: 56 | K14: 82 | L14: 38 | M14: 33 | N14: 47 | O14: 56 | P14: 24 | Q14: 18 | R14: 33 | S14: 30 | T14: 24 | U14: 53 | V14: 38 | W14: 33 | X14: 25 | Y14: 22 | Z14: 28 | AA14: 34 | AB14: 70 | AC14: 16 | AD14: 72 | AE14: 141 | AF14: 44 | AG14: 29 | AH14: 61 | AI14: 43
B15: Total fulfilled | C15: =C12+(0.5*C13) -> 415 | D15: =D12+(0.5*D13) -> 171 | E15: =E12+(0.5*E13) -> 85 | F15: =F12+(0.5*F13) -> 420 | G15: =G12+(0.5*G13) -> 75.5 | H15: =H12+(0.5*H13) -> 59.5 | I15: =I12+(0.5*I13) -> 282 | J15: =J12+(0.5*J13) -> 126.5 | ... AI15: =AI12+(0.5*AI13) -> 84.5
B16: Percentage fulfilled | C16: =C15/C11 -> 0.71061644 | D16: =D15/D11 -> 0.64044944 | E16: =E15/E11 -> 0.70247934 | F16: =F15/F11 -> 0.76363636 | G16: =G15/G11 -> 0.59920635 | H16: =H15/H11 -> 0.7 | I16: =I15/I11 -> 0.7943662 | J16: =J15/J11 -> 0.65206186 | ... AI16: =AI15/AI11 -> 0.61678832
A17: Usability Recommendations for NOT Recommended Gamification Elements (URUIGE) | B17: Total number of recommendations provided for not recommended gamification elements | C17: 95 | D17: 20 | E17: 32 | F17: 95 | G17: 7 | H17: 11 | I17: 10 | J17: 82 | K17: - | L17: - | M17: 25 | N17: 62 | O17: 124 | P17: 75 | Q17: 37 | R17: 32 | S17: 117 | T17: 27 | U17: 76 | V17: 56 | W17: 73 | X17: 6 | Y17: 11 | Z17: - | AA17: 58 | AB17: 27 | AC17: 32 | AD17: 36 | AE17: 94 | AF17: 24 | AG17: 135 | AH17: 2 | AI17: 56
B18: Fulfilled | C18: 65 | D18: 14 | E18: 17 | F18: 65 | G18: 4 | H18: 10 | I18: 7 | J18: 62 | K18: - | L18: - | M18: 20 | N18: 50 | O18: 87 | P18: 47 | Q18: 20 | R18: 15 | S18: 83 | T18: 25 | U18: 54 | V18: 30 | W18: 41 | X18: 3 | Y18: 6 | Z18: - | AA18: 24 | AB18: 15 | AC18: 20 | AD18: 17 | AE18: 42 | AF18: 20 | AG18: 59 | AH18: 0 | AI18: 30
B19: Partially fulfilled | C19: 18 | D19: 2 | E19: 5 | F19: 18 | G19: 2 | H19: 0 | I19: 1 | J19: 8 | K19: - | L19: - | M19: 1 | N19: 3 | O19: 15 | P19: 16 | Q19: 12 | R19: 11 | S19: 6 | T19: 2 | U19: 3 | V19: 7 | W19: 11 | X19: 2 | Y19: 3 | Z19: - | AA19: 8 | AB19: 3 | AC19: 3 | AD19: 5 | AE19: 18 | AF19: 3 | AG19: 32 | AH19: 1 | AI19: 8
B20: Not fulfilled | C20: 12 | D20: 4 | E20: 10 | F20: 12 | G20: 1 | H20: 1 | I20: 2 | J20: 12 | K20: - | L20: - | M20: 4 | N20: 9 | O20: 22 | P20: 12 | Q20: 5 | R20: 6 | S20: 28 | T20: 0 | U20: 19 | V20: 19 | W20: 21 | X20: 1 | Y20: 2 | Z20: - | AA20: 26 | AB20: 9 | AC20: 9 | AD20: 14 | AE20: 34 | AF20: 1 | AG20: 44 | AH20: 1 | AI20: 18
B21: Total fulfilled | C21: =C18+(0.5*C19) -> 74 | D21: =D18+(0.5*D19) -> 15 | E21: =E18+(0.5*E19) -> 19.5 | F21: =F18+(0.5*F19) -> 74 | G21: =G18+(0.5*G19) -> 5 | H21: =H18+(0.5*H19) -> 10 | I21: =I18+(0.5*I19) -> 7.5 | J21: =J18+(0.5*J19) -> 66 | K21: - | L21: - | M21: =M18+(0.5*M19) -> 20.5 | N21: =N18+(0.5*N19) -> 51.5 | O21: =O18+(0.5*O19) -> 94.5 | P21: =P18+(0.5*P19) -> 55 | Q21: =Q18+(0.5*Q19) -> 26 | R21: =R18+(0.5*R19) -> 20.5 | S21: =S18+(0.5*S19) -> 86 | T21: =T18+(0.5*T19) -> 26 | ... Y21: =Y18+(0.5*Y19) -> 7.5 | Z21: - | AA21: =AA18+(0.5*AA19) -> 28 | AB21: =AB18+(0.5*AB19) -> 16.5 | AC21: =AC18+(0.5*AC19) -> 21.5 | AD21: =AD18+(0.5*AD19) -> 19.5 | AE21: =AE18+(0.5*AE19) -> 51 | AF21: =AF18+(0.5*AF19) -> 21.5 | AG21: =AG18+(0.5*AG19) -> 75 | AH21: =AH18+(0.5*AH19) -> 0.5 | AI21: =AI18+(0.5*AI19) -> 34
B22: Percentage fulfilled | C22: =C21/C17 -> 0.77894737 | D22: =D21/D17 -> 0.75 | E22: =E21/E17 -> 0.609375 | F22: =F21/F17 -> 0.77894737 | G22: =G21/G17 -> 0.71428571 | H22: =H21/H17 -> 0.90909091 | I22: =I21/I17 -> 0.75 | J22: =J21/J17 -> 0.80487805 | K22: - | L22: - | M22: =M21/M17 -> 0.82 | N22: =N21/N17 -> 0.83064516 | O22: =O21/O17 -> 0.76209677 | P22: =P21/P17 -> 0.73333333 | Q22: =Q21/Q17 -> 0.7027027 | R22: =R21/R17 -> 0.640625 | S22: =S21/S17 -> 0.73504274 | T22: =T21/T17 -> 0.96296296 | ... Y22: =Y21/Y17 -> 0.68181818 | Z22: - | AA22: =AA21/AA17 -> 0.48275862 | AB22: =AB21/AB17 -> 0.61111111 | AC22: =AC21/AC17 -> 0.671875 | AD22: =AD21/AD17 -> 0.54166667 | AE22: =AE21/AE17 -> 0.54255319 | AF22: =AF21/AF17 -> 0.89583333 | AG22: =AG21/AG17 -> 0.55555556 | AH22: =AH21/AH17 -> 0.25 | AI22: =AI21/AI17 -> 0.60714286

Sheet Duolingo
C2: Recommended Gamification Elements | D2: Recommendations by age group and application domain | H2: ISO 9241 recommendations | L2: WCAG 2.2 recommendations
D3: Fulfilled | E3: Partially fulfilled | F3: Not fulfilled | G3: Total | H3: Fulfilled | I3: Partially fulfilled | J3: Not fulfilled | K3: Total | L3: Fulfilled | M3: Partially fulfilled | N3: Not fulfilled | O3: Total
C4: Quests | G4: =D4+E4+F4 -> 0 | H4: 40 | I4: 13 | J4: 21 | K4: =H4+I4+J4 -> 74 | M4: 1 | N4: 2 | O4: =L4+M4+N4 -> 3 | Q4: Total number of recommendations provided for recommended gamification elements | R4: =G18+K18+O18 -> 584
C5: Points | G5: =D5+E5+F5 -> 0 | H5: 17 | I5: 5 | J5: 4 | K5: =H5+I5+J5 -> 26 | L5: 2 | O5: =L5+M5+N5 -> 2 | Q5: Fulfilled | R5: =D18+H18+L18 -> 354
C6: Quizzes | D6: 2 | F6: 1 | G6: =D6+E6+F6 -> 3 | H6: 41 | I6: 17 | J6: 18 | K6: =H6+I6+J6 -> 76 | L6: 3 | M6: 1 | N6: 2 | O6: =L6+M6+N6 -> 6 | Q6: Partially fulfilled | R6: =E18+I18+M18 -> 122
C7: Challenges | F7: 1 | G7: =D7+E7+F7 -> 1 | H7: 52 | I7: 13 | J7: 12 | K7: =H7+I7+J7 -> 77 | L7: 3 | M7: 2 | N7: 1 | O7: =L7+M7+N7 -> 6 | Q7: Not fulfilled at all | R7: =F18+J18+N18 -> 108
C8: Teams | D8: 1 | G8: =D8+E8+F8 -> 1 | H8: 2 | I8: 3 | J8: 3 | K8: =H8+I8+J8 -> 8 | O8: =L8+M8+N8 -> 0 | Q8: Total fullfiled | R8: =R5+(0.5*R6) -> 415
C9: Badges | G9: =D9+E9+F9 -> 0 | H9: 20 | I9: 5 | J9: 3 | K9: =H9+I9+J9 -> 28 | L9: 1 | M9: 2 | N9: 1 | O9: =L9+M9+N9 -> 4 | Q9: Percentage fulfilled | R9: =R8/R4 -> 0.71061644
C10: Levels | F10: 1 | G10: =D10+E10+F10 -> 1 | H10: 13 | I10: 9 | J10: 1 | K10: =H10+I10+J10 -> 23 | L10: 1 | M10: 1 | O10: =L10+M10+N10 -> 2
C11: Leaderboards | G11: =D11+E11+F11 -> 0 | H11: 16 | I11: 3 | J11: 7 | K11: =H11+I11+J11 -> 26 | M11: 2 | O11: =L11+M11+N11 -> 2
C12: Tasks | D12: 2 | E12: 1 | G12: =D12+E12+F12 -> 3 | H12: 50 | I12: 13 | J12: 14 | K12: =H12+I12+J12 -> 77 | L12: 3 | M12: 2 | N12: 1 | O12: =L12+M12+N12 -> 6
C13: Status bars | G13: =D13+E13+F13 -> 0 | H13: 8 | I13: 7 | J13: 1 | K13: =H13+I13+J13 -> 16 | O13: =L13+M13+N13 -> 0
C14: Performance feedback | E14: 1 | G14: =D14+E14+F14 -> 1 | H14: 16 | I14: 4 | J14: 1 | K14: =H14+I14+J14 -> 21 | L14: 1 | O14: =L14+M14+N14 -> 1
C15: Questions | D15: 1 | G15: =D15+E15+F15 -> 1 | H15: 34 | I15: 14 | J15: 12 | K15: =H15+I15+J15 -> 60 | L15: 2 | M15: 2 | O15: =L15+M15+N15 -> 4
C16: Avatar | G16: =D16+E16+F16 -> 0 | H16: 9 | I16: 1 | J16: 1 | K16: =H16+I16+J16 -> 11 | L16: 1 | O16: =L16+M16+N16 -> 1
C17: Notifications | D17: 1 | G17: =D17+E17+F17 -> 1 | H17: 10 | K17: =H17+I17+J17 -> 10 | L17: 2 | O17: =L17+M17+N17 -> 2
C18: TOTAL | D18: =SUM(D4:D17) -> 7 | E18: =SUM(E4:E17) -> 2 | F18: =SUM(F4:F17) -> 3 | G18: =SUM(G4:G17) -> 12 | H18: =SUM(H4:H17) -> 328 | I18: =SUM(I4:I17) -> 107 | J18: =SUM(J4:J17) -> 98 | K18: =SUM(K4:K17) -> 533 | ... O18: =SUM(O4:O17) -> 39
C23: Not Recommended Gamification Elements | D23: Recommendations by age group and application domain | H23: ISO 9241 recommendations | L23: WCAG 2.2 recommendations | Q23: Total number of recommendations provided for not recommended gamification elements | R23: =G31+K31+O31 -> 95
D24: Fulfilled | E24: Partially fulfilled | F24: Not fulfilled | G24: Total | H24: Fulfilled | I24: Partially fulfilled | J24: Not fulfilled | K24: Total | L24: Fulfilled | M24: Partially fulfilled | N24: Not fulfilled | O24: Total | Q24: Usability recommendations for non-recommended elements fully met | R24: =D31+H31+L31 -> 65
C25: Streaks | G25: =D25+E25+F25 -> 0 | K25: =H25+I25+J25 -> 0 | O25: =L25+M25+N25 -> 0 | Q25: Partially met | R25: =E31+I31+M31 -> 18
C26: Retries | G26: =D26+E26+F26 -> 0 | H26: 7 | I26: 1 | K26: =H26+I26+J26 -> 8 | L26: 1 | O26: =L26+M26+N26 -> 1 | Q26: Not met at all | R26: =F31+J31+N31 -> 12
C27: Virtual currency | G27: =D27+E27+F27 -> 0 | H27: 10 | I27: 4 | J27: 4 | K27: =H27+I27+J27 -> 18 | L27: 2 | N27: 1 | O27: =L27+M27+N27 -> 3 | Q27: Total met | R27: =R24+(0.5*R25) -> 74
C28: Gifting | G28: =D28+E28+F28 -> 0 | H28: 1 | J28: 1 | K28: =H28+I28+J28 -> 2 | O28: =L28+M28+N28 -> 0 | Q28: Percentage met | R28: =R27/R23 -> 0.77894737
C29: Achievements | G29: =D29+E29+F29 -> 0 | H29: 25 | I29: 2 | J29: 2 | K29: =H29+I29+J29 -> 29 | L29: 3 | M29: 1 | O29: =L29+M29+N29 -> 4
C30: Onboarding | G30: =D30+E30+F30 -> 0 | H30: 15 | I30: 8 | J30: 4 | K30: =H30+I30+J30 -> 27 | L30: 1 | M30: 2 | O30: =L30+M30+N30 -> 3
C31: TOTAL | D31: =SUM(D25:D30) -> 0 | E31: =SUM(E25:E30) -> 0 | F31: =SUM(F25:F30) -> 0 | G31: =SUM(G25:G30) -> 0 | H31: =SUM(H25:H30) -> 58 | I31: =SUM(I25:I30) -> 15 | J31: =SUM(J25:J30) -> 11 | K31: =SUM(K25:K30) -> 84 | ... O31: =SUM(O25:O30) -> 11
C35: Description | D35: Variable | E35: Value
C36: Google Play ratings count | D36: P | E36: 37473804
C37: Good ratings count | D37: H | E37: 36349590
C38: Bad ratings count | D38: C | E38: 1124214
C39: Control parameter | D39: n | E39: 2
C40: Degree of satisfaction | D40: DoS | E40: =SIGN(E37-E38)*LOG(ABS(E37-E38)+(E36/10),E39) -> 25.215963

Sheet Duolingo ABC
C2: Recommended Gamification Elements | D2: Recommendations by age group and application domain | H2: ISO 9241 recommendations | L2: WCAG 2.2 recommendations
D3: Fulfilled | E3: Partially fulfilled | F3: Not fulfilled | G3: Total | H3: Fulfilled | I3: Partially fulfilled | J3: Not fulfilled | K3: Total | L3: Fulfilled | M3: Partially fulfilled | N3: Not fulfilled | O3: Total
C4: Rewards | F4: 1 | G4: =D4+E4+F4 -> 1 | K4: =H4+I4+J4 -> 0 | O4: =L4+M4+N4 -> 0 | Q4: Total number of recommendations provided for recommended gamification elements | R4: =G12+K12+O12 -> 267
C5: Onboarding | G5: =D5+E5+F5 -> 0 | H5: 12 | I5: 5 | J5: 8 | K5: =H5+I5+J5 -> 25 | L5: 1 | M5: 1 | N5: 1 | O5: =L5+M5+N5 -> 3 | Q5: Fulfilled | R5: =D12+H12+L12 -> 143
C6: Narrative | G6: =D6+E6+F6 -> 0 | H6: 17 | I6: 6 | J6: 7 | K6: =H6+I6+J6 -> 30 | M6: 4 | N6: 2 | O6: =L6+M6+N6 -> 6 | Q6: Partially fulfilled | R6: =E12+I12+M12 -> 56
C7: Challenges | D7: 1 | G7: =D7+E7+F7 -> 1 | H7: 44 | I7: 15 | J7: 18 | K7: =H7+I7+J7 -> 77 | L7: 1 | M7: 2 | N7: 1 | O7: =L7+M7+N7 -> 4 | Q7: Not fulfilled at all | R7: =F12+J12+N12 -> 67
C8: Tasks | D8: 4 | E8: 2 | F8: 2 | G8: =D8+E8+F8 -> 8 | H8: 43 | I8: 11 | J8: 19 | K8: =H8+I8+J8 -> 73 | L8: 1 | M8: 2 | N8: 1 | O8: =L8+M8+N8 -> 4 | Q8: Total fullfiled | R8: =R5+(0.5*R6) -> 171
C9: Levels | D9: 1 | G9: =D9+E9+F9 -> 1 | H9: 7 | I9: 4 | J9: 1 | K9: =H9+I9+J9 -> 12 | L9: 1 | O9: =L9+M9+N9 -> 1 | Q9: Percentage fulfilled | R9: =R8/R4 -> 0.64044944
C10: Avatar | G10: =D10+E10+F10 -> 0 | H10: 3 | I10: 1 | J10: 2 | K10: =H10+I10+J10 -> 6 | L10: 1 | O10: =L10+M10+N10 -> 1
C11: Full game | G11: =D11+E11+F11 -> 0 | H11: 6 | I11: 1 | J11: 2 | K11: =H11+I11+J11 -> 9 | L11: 1 | M11: 2 | N11: 2 | O11: =L11+M11+N11 -> 5
C12: TOTAL | D12: =SUM(D4:D11) -> 6 | E12: =SUM(E4:E11) -> 2 | F12: =SUM(F4:F11) -> 3 | G12: =SUM(G4:G11) -> 11 | H12: =SUM(H4:H11) -> 132 | I12: =SUM(I4:I11) -> 43 | J12: =SUM(J4:J11) -> 57 | K12: =SUM(K4:K11) -> 232 | L12: =SUM(L4:L10) -> 5 | M12: =SUM(M4:M11) -> 11 | N12: =SUM(N4:N11) -> 7 | O12: =SUM(O4:O11) -> 24
C16: Not Recommended Gamification Elements | D16: Recommendations by age group and application domain | H16: ISO 9241 recommendations | L16: WCAG 2.2 recommendations | Q16: Total number of recommendations provided for not recommended gamification elements | R16: =G24+K24+O24 -> 20
D17: Fulfilled | E17: Partially fulfilled | F17: Not fulfilled | G17: Total | H17: Fulfilled | I17: Partially fulfilled | J17: Not fulfilled | K17: Total | L17: Fulfilled | M17: Partially fulfilled | N17: Not fulfilled | O17: Total | Q17: Fulfilled | R17: =D24+H24+L24 -> 14
C18: Collection | G18: =D18+E18+F18 -> 0 | H18: 3 | I18: 1 | J18: 3 | K18: =H18+I18+J18 -> 7 | L18: 1 | O18: =L18+M18+N18 -> 1 | Q18: Partially fulfilled | R18: =E24+I24+M24 -> 2
C19: Reminders | G19: =D19+E19+F19 -> 0 | H19: 8 | I19: 1 | J19: 1 | K19: =H19+I19+J19 -> 10 | L19: 2 | O19: =L19+M19+N19 -> 2 | Q19: Not fulfilled at all | R19: =F24+J24+N24 -> 4
Q20: Total fullfiled | R20: =R17+(0.5*R18) -> 15
Q21: Percentage fulfilled | R21: =R20/R16 -> 0.75
C24: TOTAL | D24: =SUM(D18:D23) -> 0 | E24: =SUM(E18:E23) -> 0 | F24: =SUM(F18:F23) -> 0 | G24: =SUM(G18:G23) -> 0 | H24: =SUM(H18:H23) -> 11 | I24: =SUM(I18:I23) -> 2 | J24: =SUM(J18:J23) -> 4 | K24: =SUM(K18:K23) -> 17 | ... O24: =SUM(O18:O23) -> 3
C28: Description | D28: Variable | E28: Value
C29: Google Play ratings count | D29: P | E29: 17919
C30: Good ratings count | D30: H | E30: 14514
C31: Bad ratings count | D31: C | E31: 3405
C32: Control parameter | D32: n | E32: 2
C33: Degree of satisfaction | D33: DoS | E33: =SIGN(E30-E31)*LOG(ABS(E30-E31)+(E29/10),E32) -> 13.655184

Sheet Khan academy
B3: Recommended Gamification Elements | C3: Recommendations by age group and application domain | G3: ISO 9241 recommendations | K3: WCAG 2.2 recommendations
C4: Fulfilled | D4: Partially fulfilled | E4: Not fulfilled | F4: Total | G4: Fulfilled | H4: Partially fulfilled | I4: Not fulfilled | J4: Total | K4: Fulfilled | L4: Partially fulfilled | M4: Not fulfilled | N4: Total
B5: Rewards | F5: =C5+D5+E5 -> 0 | J5: =G5+H5+I5 -> 0 | N5: =K5+L5+M5 -> 0 | P5: Total number of recommendations provided for recommended gamification elements | Q5: =F20+J20+N20 -> 550
B6: Onboarding | F6: =C6+D6+E6 -> 0 | G6: 21 | H6: 7 | I6: 4 | J6: =G6+H6+I6 -> 32 | K6: 2 | M6: 1 | N6: =K6+L6+M6 -> 3 | P6: Fulfilled | Q6: =C20+G20+K20 -> 377
B7: Challenges | C7: 2 | F7: =C7+D7+E7 -> 2 | G7: 55 | H7: 12 | I7: 10 | J7: =G7+H7+I7 -> 77 | K7: 4 | L7: 1 | M7: 1 | N7: =K7+L7+M7 -> 6 | P7: Partially fulfilled | Q7: =D20+H20+L20 -> 86
B8: Assistance/virtual helpers | C8: 1 | F8: =C8+D8+E8 -> 1 | G8: 20 | H8: 12 | I8: 3 | J8: =G8+H8+I8 -> 35 | K8: 2 | N8: =K8+L8+M8 -> 2 | P8: Not fulfilled at all | Q8: =E20+I20+M20 -> 87
B9: Points | F9: =C9+D9+E9 -> 0 | G9: 15 | H9: 2 | I9: 6 | J9: =G9+H9+I9 -> 23 | K9: 1 | N9: =K9+L9+M9 -> 1 | P9: Total fullfiled | Q9: =Q6+(0.5*Q7) -> 420
B10: Quizzes | C10: 3 | F10: =C10+D10+E10 -> 3 | G10: 48 | H10: 7 | I10: 11 | J10: =G10+H10+I10 -> 66 | K10: 4 | L10: 1 | M10: 1 | N10: =K10+L10+M10 -> 6 | P10: Percentage fulfilled | Q10: =Q9/Q5 -> 0.76363636
B11: Badges | F11: =C11+D11+E11 -> 0 | G11: 16 | H11: 1 | I11: 11 | J11: =G11+H11+I11 -> 28 | K11: 3 | L11: 1 | N11: =K11+L11+M11 -> 4
B12: Levels | C12: 2 | F12: =C12+D12+E12 -> 2 | G12: 15 | H12: 2 | I12: 2 | J12: =G12+H12+I12 -> 19 | K12: 2 | N12: =K12+L12+M12 -> 2
B13: Tasks | C13: 9 | D13: 1 | F13: =C13+D13+E13 -> 10 | G13: 53 | H13: 12 | I13: 11 | J13: =G13+H13+I13 -> 76 | N13: =K13+L13+M13 -> 0
B14: Status bars | F14: =C14+D14+E14 -> 0 | G14: 10 | H14: 1 | I14: 4 | J14: =G14+H14+I14 -> 15 | N14: =K14+L14+M14 -> 0
B15: Game rules | F15: =C15+D15+E15 -> 0 | G15: 17 | H15: 6 | I15: 6 | J15: =G15+H15+I15 -> 29 | K15: 2 | N15: =K15+L15+M15 -> 2
B16: Performace feedback | C16: 2 | F16: =C16+D16+E16 -> 2 | G16: 9 | H16: 7 | I16: 2 | J16: =G16+H16+I16 -> 18 | K16: 1 | N16: =K16+L16+M16 -> 1
B17: Questions | C17: 1 | F17: =C17+D17+E17 -> 1 | G17: 39 | H17: 6 | I17: 11 | J17: =G17+H17+I17 -> 56 | K17: 3 | L17: 1 | N17: =K17+L17+M17 -> 4
B18: Avatar | F18: =C18+D18+E18 -> 0 | G18: 4 | H18: 3 | I18: 1 | J18: =G18+H18+I18 -> 8 | K18: 1 | N18: =K18+L18+M18 -> 1
B19: Notifications | C19: 1 | F19: =C19+D19+E19 -> 1 | G19: 8 | H19: 3 | I19: 2 | J19: =G19+H19+I19 -> 13 | K19: 1 | N19: =K19+L19+M19 -> 1
B20: TOTAL | C20: =SUM(C5:C19) -> 21 | D20: =SUM(D5:D19) -> 1 | E20: =SUM(E5:E19) -> 0 | F20: =SUM(F5:F19) -> 22 | G20: =SUM(G5:G19) -> 330 | H20: =SUM(H5:H19) -> 81 | I20: =SUM(I5:I19) -> 84 | J20: =SUM(J5:J19) -> 495 | ... N20: =SUM(N5:N19) -> 33
B24: Not Recommended Gamification Elements | C24: Recommendations by age group and application domain | G24: ISO 9241 recommendations | K24: WCAG 2.2 recommendations | P24: Total number of recommendations provided for not recommended gamification elements | Q24: =F32+J32+N32 -> 6
C25: Fulfilled | D25: Partially fulfilled | E25: Not fulfilled | F25: Total | G25: Fulfilled | H25: Partially fulfilled | I25: Not fulfilled | J25: Total | K25: Fulfilled | L25: Partially fulfilled | M25: Not fulfilled | N25: Total | P25: Fulfilled | Q25: =C32+G32+K32 -> 4
B26: Knowledge-sharing | F26: =C26+D26+E26 -> 0 | G26: 4 | H26: 1 | I26: 1 | J26: =G26+H26+I26 -> 6 | N26: =K26+L26+M26 -> 0 | P26: Partially fulfilled | Q26: =D32+H32+L32 -> 1
P27: Not fulfilled at all | Q27: =E32+I32+M32 -> 1
P28: Total fullfiled | Q28: =Q25+(0.5*Q26) -> 4.5
P29: Percentage fulfilled | Q29: =Q28/Q24 -> 0.75
B32: TOTAL | C32: =SUM(C26:C31) -> 0 | D32: =SUM(D26:D31) -> 0 | E32: =SUM(E26:E31) -> 0 | F32: =SUM(F26:F31) -> 0 | G32: =SUM(G26:G31) -> 4 | H32: =SUM(H26:H31) -> 1 | I32: =SUM(I26:I31) -> 1 | J32: =SUM(J26:J31) -> 6 | ... N32: =SUM(N26:N31) -> 0
B36: Description | C36: Variable | D36: Value
B37: Google Play ratings count | C37: P | D37: 169688
B38: Good ratings count | C38: H | D38: 139144
B39: Bad ratings count | C39: C | D39: 30544
B40: Control parameter | C40: n | D40: 2
B41: Degree of satisfaction | C41: DoS | D41: =SIGN(D38-D39)*LOG(ABS(D38-D39)+(D37/10),D40) -> 16.938119

Sheet Khan academy kids
B3: Recommended Gamification Elements | C3: Recommendations by age group and application domain | G3: ISO 9241 recommendations | K3: WCAG 2.2 recommendations
C4: Fulfilled | D4: Partially fulfilled | E4: Not fulfilled | F4: Total | G4: Fulfilled | H4: Partially fulfilled | I4: Not fulfilled | J4: Total | K4: Fulfilled | L4: Partially fulfilled | M4: Not fulfilled | N4: Total
B5: Rewards | E5: 1 | F5: =C5+D5+E5 -> 1 | J5: =G5+H5+I5 -> 0 | N5: =K5+L5+M5 -> 0 | P5: Total number of recommendations provided for recommended gamification elements | Q5: =F20+J20+N20 -> 126
B6: Full game | F6: =C6+D6+E6 -> 0 | G6: 2 | H6: 4 | I6: 3 | J6: =G6+H6+I6 -> 9 | K6: 1 | M6: 4 | N6: =K6+L6+M6 -> 5 | P6: Fulfilled | Q6: =C20+G20+K20 -> 65
B7: Narrative | F7: =C7+D7+E7 -> 0 | G7: 11 | H7: 5 | I7: 7 | J7: =G7+H7+I7 -> 23 | K7: 1 | M7: 3 | N7: =K7+L7+M7 -> 4 | P7: Partially fulfilled | Q7: =D20+H20+L20 -> 21
B8: Tasks | C8: 5 | D8: 1 | E8: 2 | F8: =C8+D8+E8 -> 8 | G8: 36 | H8: 11 | I8: 18 | J8: =G8+H8+I8 -> 65 | K8: 4 | M8: 1 | N8: =K8+L8+M8 -> 5 | P8: Not fulfilled at all | Q8: =E20+I20+M20 -> 40
B9: Avatar | F9: =C9+D9+E9 -> 0 | G9: 4 | I9: 1 | J9: =G9+H9+I9 -> 5 | K9: 1 | N9: =K9+L9+M9 -> 1 | P9: Total fullfiled | Q9: =Q6+(0.5*Q7) -> 75.5
F10: =C10+D10+E10 -> 0 | J10: =G10+H10+I10 -> 0 | N10: =K10+L10+M10 -> 0 | P10: Percentage fulfilled | Q10: =Q9/Q5 -> 0.59920635
F11: =C11+D11+E11 -> 0 | J11: =G11+H11+I11 -> 0 | N11: =K11+L11+M11 -> 0
F12: =C12+D12+E12 -> 0 | J12: =G12+H12+I12 -> 0 | N12: =K12+L12+M12 -> 0
F13: =C13+D13+E13 -> 0 | J13: =G13+H13+I13 -> 0 | N13: =K13+L13+M13 -> 0
F14: =C14+D14+E14 -> 0 | J14: =G14+H14+I14 -> 0 | N14: =K14+L14+M14 -> 0
F15: =C15+D15+E15 -> 0 | J15: =G15+H15+I15 -> 0 | N15: =K15+L15+M15 -> 0
F16: =C16+D16+E16 -> 0 | J16: =G16+H16+I16 -> 0 | N16: =K16+L16+M16 -> 0
F17: =C17+D17+E17 -> 0 | J17: =G17+H17+I17 -> 0 | N17: =K17+L17+M17 -> 0
F18: =C18+D18+E18 -> 0 | J18: =G18+H18+I18 -> 0 | N18: =K18+L18+M18 -> 0
F19: =C19+D19+E19 -> 0 | J19: =G19+H19+I19 -> 0 | N19: =K19+L19+M19 -> 0
B20: TOTAL | C20: =SUM(C5:C19) -> 5 | D20: =SUM(D5:D19) -> 1 | E20: =SUM(E5:E19) -> 3 | F20: =SUM(F5:F19) -> 9 | G20: =SUM(G5:G19) -> 53 | H20: =SUM(H5:H19) -> 20 | I20: =SUM(I5:I19) -> 29 | J20: =SUM(J5:J19) -> 102 | ... N20: =SUM(N5:N19) -> 15
B24: Not Recommended Gamification Elements | C24: Recommendations by age group and application domain | G24: ISO 9241 recommendations | K24: WCAG 2.2 recommendations | P24: Total number of recommendations provided for not recommended gamification elements | Q24: =F32+J32+N32 -> 7
C25: Fulfilled | D25: Partially fulfilled | E25: Not fulfilled | F25: Total | G25: Fulfilled | H25: Partially fulfilled | I25: Not fulfilled | J25: Total | K25: Fulfilled | L25: Partially fulfilled | M25: Not fulfilled | N25: Total | P25: Fulfilled | Q25: =C32+G32+K32 -> 4
B26: Collections | F26: =C26+D26+E26 -> 0 | G26: 3 | H26: 2 | I26: 1 | J26: =G26+H26+I26 -> 6 | K26: 1 | N26: =K26+L26+M26 -> 1 | P26: Partially fulfilled | Q26: =D32+H32+L32 -> 2
F27: =C27+D27+E27 -> 0 | J27: =G27+H27+I27 -> 0 | N27: =K27+L27+M27 -> 0 | P27: Not fulfilled at all | Q27: =E32+I32+M32 -> 1
F28: =C28+D28+E28 -> 0 | J28: =G28+H28+I28 -> 0 | N28: =K28+L28+M28 -> 0 | P28: Total fullfiled | Q28: =Q25+(0.5*Q26) -> 5
F29: =C29+D29+E29 -> 0 | J29: =G29+H29+I29 -> 0 | N29: =K29+L29+M29 -> 0 | P29: Percentage fulfilled | Q29: =Q28/Q24 -> 0.71428571
F30: =C30+D30+E30 -> 0 | J30: =G30+H30+I30 -> 0 | N30: =K30+L30+M30 -> 0
F31: =C31+D31+E31 -> 0 | J31: =G31+H31+I31 -> 0 | N31: =K31+L31+M31 -> 0
B32: TOTAL | C32: =SUM(C26:C31) -> 0 | D32: =SUM(D26:D31) -> 0 | E32: =SUM(E26:E31) -> 0 | F32: =SUM(F26:F31) -> 0 | G32: =SUM(G26:G31) -> 3 | H32: =SUM(H26:H31) -> 2 | I32: =SUM(I26:I31) -> 1 | J32: =SUM(J26:J31) -> 6 | ... N32: =SUM(N26:N31) -> 1
B36: Description | C36: Variable | D36: Value
B37: Google Play ratings count | C37: P | D37: 52204
B38: Good ratings count | C38: H | D38: 49072
B39: Bad ratings count | C39: C | D39: 3132
B40: Control parameter | C40: n | D40: 2
